Workbook

Sheet PROG_ADR
A1: ProgramNo | B1: Program | C1: M_START | D1: M_END | E1: M_POINT | F1: D_START | G1: D_END | H1: D_POINT | I1: T_START | J1: T_END | K1: T_POINT | L1: X_START | M1: X_END | N1: X_POINT | O1: Y_START | P1: Y_END | Q1: Y_POINT | R1: UNIT_NO | S1: CYL_S_CNT | T1: CYL_M_CNT | U1: CYL_O_CNT | V1: CYL_E_CNT | W1: VAC_S_CNT | X1: VAC_M_CNT | Y1: VAC_O_CNT | Z1: VAC_E_CNT | AA1: MT_M_CNT | AB1: MT_O_CNT | AC1: CYC_M_CNT
A2: 3 | B2: NGICV1 | C2: 3000 | D2: =C2+E2-1 -> 3499 | E2: 500 | F2: 3000 | G2: =F2+H2-1 -> 3499 | H2: 500 | I2: 3000 | J2: =I2+K2-1 -> 3099 | K2: 100 | L2: 700 | M2: =DEC2HEX(HEX2DEC(L2)+N2-1) -> 73F | N2: 64 | O2: 700 | P2: =DEC2HEX(HEX2DEC(O2)+Q2-1) -> 73F | Q2: 64 | R2: 0 | S2: 6 | T2: 6 | U2: 6 | V2: 0 | W2: 0 | X2: 0 | Y2: 0 | Z2: 0 | AA2: 3 | AB2: 3 | AC2: 0
A3: 4 | B3: NGICV2 | C3: 3500 | D3: =C3+E3-1 -> 3999 | E3: 500 | F3: 3500 | G3: =F3+H3-1 -> 3999 | H3: 500 | I3: 3100 | J3: =I3+K3-1 -> 3199 | K3: 100 | L3: =DEC2HEX(HEX2DEC(M2)+1) -> 740 | M3: =DEC2HEX(HEX2DEC(L3)+N3-1) -> 77F | N3: 64 | O3: =DEC2HEX(HEX2DEC(P2)+1) -> 740 | P3: =DEC2HEX(HEX2DEC(O3)+Q3-1) -> 77F | Q3: 64 | R3: 0 | S3: 6 | T3: 6 | U3: 6 | V3: 0 | W3: 0 | X3: 0 | Y3: 0 | Z3: 0 | AA3: 3 | AB3: 3 | AC3: 0
A4: 5 | B4: NGLF_Z | C4: 4000 | D4: =C4+E4-1 -> 4499 | E4: 500 | F4: 4000 | G4: =F4+H4-1 -> 4499 | H4: 500 | I4: 3200 | J4: =I4+K4-1 -> 3299 | K4: 100 | L4: =DEC2HEX(HEX2DEC(M3)+1) -> 780 | M4: =DEC2HEX(HEX2DEC(L4)+N4-1) -> 7BF | N4: 64 | O4: =DEC2HEX(HEX2DEC(P3)+1) -> 780 | P4: =DEC2HEX(HEX2DEC(O4)+Q4-1) -> 7BF | Q4: 64 | R4: 0 | S4: 6 | T4: 6 | U4: 6 | V4: 0 | W4: 0 | X4: 0 | Y4: 0 | Z4: 0 | AA4: 3 | AB4: 3 | AC4: 0
A5: 6 | B5: NGSPE | C5: 4500 | D5: =C5+E5-1 -> 4999 | E5: 500 | F5: 4500 | G5: =F5+H5-1 -> 4999 | H5: 500 | I5: 3300 | J5: =I5+K5-1 -> 3399 | K5: 100 | L5: =DEC2HEX(HEX2DEC(M4)+1) -> 7C0 | M5: =DEC2HEX(HEX2DEC(L5)+N5-1) -> 7FF | N5: 64 | O5: =DEC2HEX(HEX2DEC(P4)+1) -> 7C0 | P5: =DEC2HEX(HEX2DEC(O5)+Q5-1) -> 7FF | Q5: 64 | R5: 0 | S5: 6 | T5: 6 | U5: 6 | V5: 0 | W5: 0 | X5: 0 | Y5: 0 | Z5: 0 | AA5: 3 | AB5: 3 | AC5: 0
A6: 7 | B6: NGO_CV | C6: 5000 | D6: =C6+E6-1 -> 5499 | E6: 500 | F6: 5000 | G6: =F6+H6-1 -> 5499 | H6: 500 | I6: 3400 | J6: =I6+K6-1 -> 3499 | K6: 100 | L6: =DEC2HEX(HEX2DEC(M5)+1) -> 800 | M6: =DEC2HEX(HEX2DEC(L6)+N6-1) -> 83F | N6: 64 | O6: =DEC2HEX(HEX2DEC(P5)+1) -> 800 | P6: =DEC2HEX(HEX2DEC(O6)+Q6-1) -> 83F | Q6: 64 | R6: 0 | S6: 6 | T6: 6 | U6: 6 | V6: 0 | W6: 0 | X6: 0 | Y6: 0 | Z6: 0 | AA6: 3 | AB6: 3 | AC6: 0
A7: 8 | B7: BOXICV | C7: 5500 | D7: =C7+E7-1 -> 5999 | E7: 500 | F7: 5500 | G7: =F7+H7-1 -> 5999 | H7: 500 | I7: 3500 | J7: =I7+K7-1 -> 3599 | K7: 100 | L7: =DEC2HEX(HEX2DEC(M6)+1) -> 840 | M7: =DEC2HEX(HEX2DEC(L7)+N7-1) -> 87F | N7: 64 | O7: =DEC2HEX(HEX2DEC(P6)+1) -> 840 | P7: =DEC2HEX(HEX2DEC(O7)+Q7-1) -> 87F | Q7: 64 | R7: 0 | S7: 6 | T7: 6 | U7: 6 | V7: 0 | W7: 0 | X7: 0 | Y7: 0 | Z7: 0 | AA7: 3 | AB7: 3 | AC7: 0
A8: 9 | B8: BOXSPE | C8: 6000 | D8: =C8+E8-1 -> 6499 | E8: 500 | F8: 6000 | G8: =F8+H8-1 -> 6499 | H8: 500 | I8: 3600 | J8: =I8+K8-1 -> 3699 | K8: 100 | L8: =DEC2HEX(HEX2DEC(M7)+1) -> 880 | M8: =DEC2HEX(HEX2DEC(L8)+N8-1) -> 8BF | N8: 64 | O8: =DEC2HEX(HEX2DEC(P7)+1) -> 880 | P8: =DEC2HEX(HEX2DEC(O8)+Q8-1) -> 8BF | Q8: 64 | R8: 0 | S8: 6 | T8: 6 | U8: 6 | V8: 0 | W8: 0 | X8: 0 | Y8: 0 | Z8: 0 | AA8: 3 | AB8: 3 | AC8: 0
A9: 10 | B9: BOX_LF | C9: 6500 | D9: =C9+E9-1 -> 6999 | E9: 500 | F9: 6500 | G9: =F9+H9-1 -> 6999 | H9: 500 | I9: 3700 | J9: =I9+K9-1 -> 3799 | K9: 100 | L9: =DEC2HEX(HEX2DEC(M8)+1) -> 8C0 | M9: =DEC2HEX(HEX2DEC(L9)+N9-1) -> 8FF | N9: 64 | O9: =DEC2HEX(HEX2DEC(P8)+1) -> 8C0 | P9: =DEC2HEX(HEX2DEC(O9)+Q9-1) -> 8FF | Q9: 64 | R9: 0 | S9: 6 | T9: 6 | U9: 6 | V9: 0 | W9: 0 | X9: 0 | Y9: 0 | Z9: 0 | AA9: 3 | AB9: 3 | AC9: 0
A10: 11 | B10: B_L_CV | C10: 7000 | D10: =C10+E10-1 -> 7499 | E10: 500 | F10: 7000 | G10: =F10+H10-1 -> 7499 | H10: 500 | I10: 3800 | J10: =I10+K10-1 -> 3899 | K10: 100 | L10: =DEC2HEX(HEX2DEC(M9)+1) -> 900 | M10: =DEC2HEX(HEX2DEC(L10)+N10-1) -> 93F | N10: 64 | O10: =DEC2HEX(HEX2DEC(P9)+1) -> 900 | P10: =DEC2HEX(HEX2DEC(O10)+Q10-1) -> 93F | Q10: 64 | R10: 0 | S10: 6 | T10: 6 | U10: 6 | V10: 0 | W10: 0 | X10: 0 | Y10: 0 | Z10: 0 | AA10: 3 | AB10: 3 | AC10: 0
A11: 12 | B11: B_OCV1 | C11: 7500 | D11: =C11+E11-1 -> 7999 | E11: 500 | F11: 7500 | G11: =F11+H11-1 -> 7999 | H11: 500 | I11: 3900 | J11: =I11+K11-1 -> 3999 | K11: 100 | L11: =DEC2HEX(HEX2DEC(M10)+1) -> 940 | M11: =DEC2HEX(HEX2DEC(L11)+N11-1) -> 97F | N11: 64 | O11: =DEC2HEX(HEX2DEC(P10)+1) -> 940 | P11: =DEC2HEX(HEX2DEC(O11)+Q11-1) -> 97F | Q11: 64 | R11: 0 | S11: 6 | T11: 6 | U11: 6 | V11: 0 | W11: 0 | X11: 0 | Y11: 0 | Z11: 0 | AA11: 3 | AB11: 3 | AC11: 0
A12: 13 | B12: B_OCV2 | C12: 8000 | D12: =C12+E12-1 -> 8499 | E12: 500 | F12: 8000 | G12: =F12+H12-1 -> 8499 | H12: 500 | I12: 4000 | J12: =I12+K12-1 -> 4099 | K12: 100 | L12: =DEC2HEX(HEX2DEC(M11)+1) -> 980 | M12: =DEC2HEX(HEX2DEC(L12)+N12-1) -> 9BF | N12: 64 | O12: =DEC2HEX(HEX2DEC(P11)+1) -> 980 | P12: =DEC2HEX(HEX2DEC(O12)+Q12-1) -> 9BF | Q12: 64 | R12: 0 | S12: 6 | T12: 6 | U12: 6 | V12: 0 | W12: 0 | X12: 0 | Y12: 0 | Z12: 0 | AA12: 3 | AB12: 3 | AC12: 0
A13: 14 | B13: PNL_TR | C13: 8500 | D13: =C13+E13-1 -> 8999 | E13: 500 | F13: 8500 | G13: =F13+H13-1 -> 8999 | H13: 500 | I13: 4100 | J13: =I13+K13-1 -> 4199 | K13: 100 | L13: =DEC2HEX(HEX2DEC(M12)+1) -> 9C0 | M13: =DEC2HEX(HEX2DEC(L13)+N13-1) -> 9FF | N13: 64 | O13: =DEC2HEX(HEX2DEC(P12)+1) -> 9C0 | P13: =DEC2HEX(HEX2DEC(O13)+Q13-1) -> 9FF | Q13: 64 | R13: 0 | S13: 6 | T13: 6 | U13: 6 | V13: 0 | W13: 0 | X13: 0 | Y13: 0 | Z13: 0 | AA13: 3 | AB13: 3 | AC13: 0
A14: 15 | B14: PAP_LF | C14: 9000 | D14: =C14+E14-1 -> 9499 | E14: 500 | F14: 9000 | G14: =F14+H14-1 -> 9499 | H14: 500 | I14: 4200 | J14: =I14+K14-1 -> 4299 | K14: 100 | L14: =DEC2HEX(HEX2DEC(M13)+1) -> A00 | M14: =DEC2HEX(HEX2DEC(L14)+N14-1) -> A3F | N14: 64 | O14: =DEC2HEX(HEX2DEC(P13)+1) -> A00 | P14: =DEC2HEX(HEX2DEC(O14)+Q14-1) -> A3F | Q14: 64 | R14: 0 | S14: 6 | T14: 6 | U14: 6 | V14: 0 | W14: 0 | X14: 0 | Y14: 0 | Z14: 0 | AA14: 3 | AB14: 3 | AC14: 0
A15: 16 | B15: PAP_TR | C15: 9500 | D15: =C15+E15-1 -> 9999 | E15: 500 | F15: 9500 | G15: =F15+H15-1 -> 9999 | H15: 500 | I15: 4300 | J15: =I15+K15-1 -> 4399 | K15: 100 | L15: =DEC2HEX(HEX2DEC(M14)+1) -> A40 | M15: =DEC2HEX(HEX2DEC(L15)+N15-1) -> A7F | N15: 64 | O15: =DEC2HEX(HEX2DEC(P14)+1) -> A40 | P15: =DEC2HEX(HEX2DEC(O15)+Q15-1) -> A7F | Q15: 64 | R15: 0 | S15: 6 | T15: 6 | U15: 6 | V15: 0 | W15: 0 | X15: 0 | Y15: 0 | Z15: 0 | AA15: 3 | AB15: 3 | AC15: 0
A16: UNIT | C16: 1000 | D16: =C16+E16-1 -> 1049 | E16: 50 | R16: 1 | S16: ACF1
R17: 2 | S17: ACF2
R18: 3 | S18: MB
R19: 4 | S19: PNL
R20: 5 | S20: TLU
R21: 6 | S21: FTR

Sheet UNIT_MOTOR
A1: Program No | B1: 1 | C1: 2 | D1: 3 | E1: 4 | F1: 5 | G1: 6 | H1: 7 | I1: 8 | J1: 9 | K1: 10
A2: 3 | B2: 33 | C2: 34
A3: 4 | B3: 17 | C3: 18
A4: 5 | B4: 69 | C4: 35 | D4: 65 | E4: 37 | F4: 39
A5: 6 | B5: 70 | C5: 36 | D5: 38
A6: 7 | B6: 20 | C6: 21 | D6: 22 | E6: 23 | F6: 27
A7: 8 | B7: 49 | C7: 51 | D7: 55 | E7: 56
A8: 9 | B8: 57 | C8: 50 | D8: 52 | E8: 54 | F8: 53
A9: 10 | B9: 1 | C9: 2 | D9: 5 | E9: 6 | F9: 9 | G9: 10 | H9: 13 | I9: 14
A10: 11 | B10: 67
A11: 12 | B11: 3 | C11: 4 | D11: 7 | E11: 8 | F11: 11 | G11: 12 | H11: 15 | I11: 16
A12: 13 | B12: 68
A13: 14 | B13: 24 | C13: 25
A14: 15 | B14: 26
A15: 16 | B15: 28 | C15: 29

Sheet UNIT_ADR
A1: CAT | B1: M_START | C1: M_END | D1: M_POINT | E1: D_START | F1: D_END | G1: D_POINT | H1: T_START | I1: T_END | J1: T_POINT | K1: CYL_START | L1: CYL_OFFS | M1: CYL_TYPE | N1: T_CYL | O1: VAC_START | P1: VAC_OFFS | Q1: VAC_TYPE | R1: T_VAC | S1: MT_START | T1: MT_OFFS | U1: MT_TYPE | V1: CYC_START | W1: CYC_OFFS | X1: CYC_TYPE
A2: STATUS | B2: 0 | C2: =B2+D2-1 -> 99 | D2: 100 | E2: 0 | F2: =E2+G2-1 -> 99 | G2: 100 | H2: 0 | I2: =H2+J2-1 -> 99 | J2: 100 | K2: =IF(M2="M",$B2+L2, $E2+ L2) -> 10 | L2: 10 | M2: M | N2: =K2 -> 10 | O2: =IF(Q2="M",$B2+P2, $E2+ P2) -> 0 | P2: 0 | Q2: M | R2: =O2 -> 0
A3: MANUAL | B3: =C2+1 -> 100 | C3: =B3+D3-1 -> 149 | D3: 50 | E3: =F2+1 -> 100 | F3: =E3+G3-1 -> 149 | G3: 50 | H3: =I2+1 -> 100 | I3: =H3+J3-1 -> 149 | J3: 50 | K3: =IF(M3="M",$B3+L3, $E3+ L3) -> 110 | L3: 10 | M3: D | O3: =IF(Q3="M",$B3+P3, $E3+ P3) -> 100 | P3: 0 | Q3: D | S3: =IF(U3="M",$B3+T3, $E3+ T3) -> 130 | T3: 30 | U3: D | V3: =IF(X3="M",$B3+W3, $E3+ W3) -> 100 | W3: 0 | X3: D
A4: READY | B4: =C3+1 -> 150 | C4: =B4+D4-1 -> 249 | D4: 100 | E4: =F3+1 -> 150 | F4: =E4+G4-1 -> 249 | G4: 100 | H4: =I3+1 -> 150 | I4: =H4+J4-1 -> 249 | J4: 100
A5: AUTO | B5: =C4+1 -> 250 | C5: =B5+D5-1 -> 449 | D5: 200 | E5: =F4+1 -> 250 | F5: =E5+G5-1 -> 449 | G5: 200 | H5: =I4+1 -> 250 | I5: =H5+J5-1 -> 449 | J5: 200
A6: OUTPUT | B6: =C5+1 -> 450 | C6: =B6+D6-1 -> 499 | D6: 50 | E6: =F5+1 -> 450 | F6: =E6+G6-1 -> 499 | G6: 50 | H6: =I5+1 -> 450 | I6: =H6+J6-1 -> 499 | J6: 50 | K6: =IF(M6="M",$B6+L6, $E6+ L6) -> 460 | L6: 10 | M6: D | O6: =IF(Q6="M",$B6+P6, $E6+ P6) -> 450 | P6: 0 | Q6: D | S6: =IF(U6="M",$B6+T6, $E6+ T6) -> 480 | T6: 30 | U6: D
A7: ERROR | B7: =C6+1 -> 500 | C7: =B7+D7-1 -> 499 | D7: 0 | E7: =F6+1 -> 500 | F7: =E7+G7-1 -> 499 | G7: 0 | H7: =I6+1 -> 500 | I7: =H7+J7-1 -> 499 | J7: 0 | K7: =IF(M7="M",$B7+L7, $E7+ L7) -> 500 | L7: 0 | M7: M | N7: =K7 -> 500 | O7: =IF(Q7="M",$B7+P7, $E7+ P7) -> 500 | P7: 0 | Q7: M | R7: =O7 -> 500 | S7: =IF(U7="M",$B7+T7, $E7+ T7) -> 500 | T7: 0 | U7: D

Sheet LADDER_FORM
B2: LD | C2: SM400
B3: OUT | C3: M3000
B4: OUT | C4: M3300
B5: OUT | C5: M3400
B6: OUT | C6: M3500
B7: OUT | C7: M3700
B8: OUT | C8: M3800
A9: [Title]Unit Status Program
A10: Unit Cylinder Check
B11: LD | C11: M3000
B12: MPS
B13: AND | C13: F13
B14: ANI | C14: F13
B15: OUT | C15: T3010
C16: K3
B17: MPP
B18: AND | C18: T3010
B19: OUT | C19: M3010
B20: LD | C20: M3000
B21: MPS
B22: ANI | C22: F13
B23: AND | C23: F13
B24: OUT | C24: T3011
C25: K3
B26: MPP
B27: AND | C27: T3011
B28: OUT | C28: M3011
B29: LD | C29: M3000
B30: MPS
B31: AND | C31: F13
B32: ANI | C32: F13
B33: OUT | C33: T3012
C34: K3
B35: MPP
B36: AND | C36: T3012
B37: OUT | C37: M3012
B38: LD | C38: M3000
B39: MPS
B40: ANI | C40: F13
B41: AND | C41: F13
...

Sheet UNIT_COMMENT_MECRO
A1: ProgramNo | B1: M_START | D1: No | E1: M_ADR | F1: COMMENT1 | G1: COMMENT2 | H1: COMMENT3 | I1: COMMENT4 | J1: Result | K1: Example | L1: D_ADR | M1: BIT | N1: COMMENT1 | O1: COMMENT2 | P1: COMMENT3 | Q1: COMMENT4 | R1: Result | S1: Example
A2: 16 | B2: =VLOOKUP(A2,PROG_ADR!$A$2:$Q$15,3) -> 9500 | D2: 0 | E2: =B2 -> 9500 | F2: =IF(K2="","",($B$7 & " ")) -> PAP_TR | G2: =MID($K2, 9, 8) -> Program | H2: =MID($K2, 17, 8) | I2: ="[" &$B$7 & "]" -> [PAP_TR] | J2: {=IF(F2="","",_xlfn.LAMBDA(_xlpm.x,LEFT(_xlpm.x&REPT(" ",8),8))($F2) & _xlfn.LAMBDA(_xlpm.x,LEFT(_xlpm.x&REPT(" ",8),8))($G2) & _xlfn.LAMBDA(_xlpm.x,LEFT(_xlpm.x&REPT(" ",8),8))($H2) & _xlfn.LAMBDA(_xlpm.x,LEFT(_xlpm.x&REPT(" ",8),8))($I2))} -> PAP_TR Program [PAP_TR] | K2: NGICV1 Program [NGICV1] | L2: =$B$4 -> 9500 | M2: - | N2: =LEFT($S2, 8) | O2: =MID($S2, 9, 8) | P2: =MID($S2, 17, 8) | Q2: ="[" &$B$7 & "]" -> [PAP_TR] | R2: {=IF(N2="","",(_xlfn.LAMBDA(_xlpm.x,LEFT(_xlpm.x&REPT(" ",8),8))($N2) & _xlfn.LAMBDA(_xlpm.x,LEFT(_xlpm.x&REPT(" ",8),8))($O2) & _xlfn.LAMBDA(_xlpm.x,LEFT(_xlpm.x&REPT(" ",8),8))(P2) & _xlfn.LAMBDA(_xlpm.x,LEFT(_xlpm.x&REPT(" ",8),8))($Q2)))}
B3: D_START | D3: =D2+1 -> 1 | E3: =E2+1 -> 9501 | F3: =IF(K3="","",($B$7 & " ")) | G3: =MID($K3, 9, 8) | H3: =MID($K3, 17, 8) | I3: ="[" &$B$7 & "]" -> [PAP_TR] | J3: {=IF(F3="","",_xlfn.LAMBDA(_xlpm.x,LEFT(_xlpm.x&REPT(" ",8),8))($F3) & _xlfn.LAMBDA(_xlpm.x,LEFT(_xlpm.x&REPT(" ",8),8))($G3) & _xlfn.LAMBDA(_xlpm.x,LEFT(_xlpm.x&REPT(" ",8),8))($H3) & _xlfn.LAMBDA(_xlpm.x,LEFT(_xlpm.x&REPT(" ",8),8))($I3))} | L3: =L2 -> 9500 | M3: 0 | N3: =LEFT($S3, 8) | O3: =MID($S3, 9, 8) | P3: =MID($S3, 17, 8) | Q3: ="[" &$B$7 & "]" -> [PAP_TR] | R3: {=IF(N3="","",(_xlfn.LAMBDA(_xlpm.x,LEFT(_xlpm.x&REPT(" ",8),8))($N3) & _xlfn.LAMBDA(_xlpm.x,LEFT(_xlpm.x&REPT(" ",8),8))($O3) & _xlfn.LAMBDA(_xlpm.x,LEFT(_xlpm.x&REPT(" ",8),8))(P3) & _xlfn.LAMBDA(_xlpm.x,LEFT(_xlpm.x&REPT(" ",8),8))($Q3)))}
B4: =VLOOKUP($A$2,PROG_ADR!$A$2:$Q$15,6,FALSE) -> 9500 | D4: =D3+1 -> 2 | E4: =E3+1 -> 9502 | F4: =IF(K4="","",($B$7 & " ")) | G4: =MID($K4, 9, 8) | H4: =MID($K4, 17, 8) | I4: ="[" &$B$7 & "]" -> [PAP_TR] | J4: {=IF(F4="","",_xlfn.LAMBDA(_xlpm.x,LEFT(_xlpm.x&REPT(" ",8),8))($F4) & _xlfn.LAMBDA(_xlpm.x,LEFT(_xlpm.x&REPT(" ",8),8))($G4) & _xlfn.LAMBDA(_xlpm.x,LEFT(_xlpm.x&REPT(" ",8),8))($H4) & _xlfn.LAMBDA(_xlpm.x,LEFT(_xlpm.x&REPT(" ",8),8))($I4))} | L4: =L3 -> 9500 | M4: =DEC2HEX(HEX2DEC(M3)+1) -> 1 | N4: =LEFT($S4, 8) | O4: =MID($S4, 9, 8) | P4: =MID($S4, 17, 8) | Q4: ="[" &$B$7 & "]" -> [PAP_TR] | R4: {=IF(N4="","",(_xlfn.LAMBDA(_xlpm.x,LEFT(_xlpm.x&REPT(" ",8),8))($N4) & _xlfn.LAMBDA(_xlpm.x,LEFT(_xlpm.x&REPT(" ",8),8))($O4) & _xlfn.LAMBDA(_xlpm.x,LEFT(_xlpm.x&REPT(" ",8),8))(P4) & _xlfn.LAMBDA(_xlpm.x,LEFT(_xlpm.x&REPT(" ",8),8))($Q4)))}
B5: T_START | D5: =D4+1 -> 3 | E5: =E4+1 -> 9503 | F5: =IF(K5="","",($B$7 & " ")) | G5: =MID($K5, 9, 8) | H5: =MID($K5, 17, 8) | I5: ="[" &$B$7 & "]" -> [PAP_TR] | J5: {=IF(F5="","",_xlfn.LAMBDA(_xlpm.x,LEFT(_xlpm.x&REPT(" ",8),8))($F5) & _xlfn.LAMBDA(_xlpm.x,LEFT(_xlpm.x&REPT(" ",8),8))($G5) & _xlfn.LAMBDA(_xlpm.x,LEFT(_xlpm.x&REPT(" ",8),8))($H5) & _xlfn.LAMBDA(_xlpm.x,LEFT(_xlpm.x&REPT(" ",8),8))($I5))} | L5: =L4 -> 9500 | M5: =DEC2HEX(HEX2DEC(M4)+1) -> 2 | N5: =LEFT($S5, 8) | O5: =MID($S5, 9, 8) | P5: =MID($S5, 17, 8) | Q5: ="[" &$B$7 & "]" -> [PAP_TR] | R5: {=IF(N5="","",(_xlfn.LAMBDA(_xlpm.x,LEFT(_xlpm.x&REPT(" ",8),8))($N5) & _xlfn.LAMBDA(_xlpm.x,LEFT(_xlpm.x&REPT(" ",8),8))($O5) & _xlfn.LAMBDA(_xlpm.x,LEFT(_xlpm.x&REPT(" ",8),8))(P5) & _xlfn.LAMBDA(_xlpm.x,LEFT(_xlpm.x&REPT(" ",8),8))($Q5)))}
B6: =VLOOKUP($A$2,PROG_ADR!$A$2:$Q$15,9,FALSE) -> 4300 | D6: =D5+1 -> 4 | E6: =E5+1 -> 9504 | F6: =IF(K6="","",($B$7 & " ")) | G6: =MID($K6, 9, 8) | H6: =MID($K6, 17, 8) | I6: ="[" &$B$7 & "]" -> [PAP_TR] | J6: {=IF(F6="","",_xlfn.LAMBDA(_xlpm.x,LEFT(_xlpm.x&REPT(" ",8),8))($F6) & _xlfn.LAMBDA(_xlpm.x,LEFT(_xlpm.x&REPT(" ",8),8))($G6) & _xlfn.LAMBDA(_xlpm.x,LEFT(_xlpm.x&REPT(" ",8),8))($H6) & _xlfn.LAMBDA(_xlpm.x,LEFT(_xlpm.x&REPT(" ",8),8))($I6))} | L6: =L5 -> 9500 | M6: =DEC2HEX(HEX2DEC(M5)+1) -> 3 | N6: =LEFT($S6, 8) | O6: =MID($S6, 9, 8) | P6: =MID($S6, 17, 8) | Q6: ="[" &$B$7 & "]" -> [PAP_TR] | R6: {=IF(N6="","",(_xlfn.LAMBDA(_xlpm.x,LEFT(_xlpm.x&REPT(" ",8),8))($N6) & _xlfn.LAMBDA(_xlpm.x,LEFT(_xlpm.x&REPT(" ",8),8))($O6) & _xlfn.LAMBDA(_xlpm.x,LEFT(_xlpm.x&REPT(" ",8),8))(P6) & _xlfn.LAMBDA(_xlpm.x,LEFT(_xlpm.x&REPT(" ",8),8))($Q6)))}
B7: =VLOOKUP($A$2,PROG_ADR!$A$2:$B$15,2,FALSE) -> PAP_TR | D7: =D6+1 -> 5 | E7: =E6+1 -> 9505 | F7: =IF(K7="","",($B$7 & " ")) | G7: =MID($K7, 9, 8) | H7: =MID($K7, 17, 8) | I7: ="[" &$B$7 & "]" -> [PAP_TR] | J7: {=IF(F7="","",_xlfn.LAMBDA(_xlpm.x,LEFT(_xlpm.x&REPT(" ",8),8))($F7) & _xlfn.LAMBDA(_xlpm.x,LEFT(_xlpm.x&REPT(" ",8),8))($G7) & _xlfn.LAMBDA(_xlpm.x,LEFT(_xlpm.x&REPT(" ",8),8))($H7) & _xlfn.LAMBDA(_xlpm.x,LEFT(_xlpm.x&REPT(" ",8),8))($I7))} | L7: =L6 -> 9500 | M7: =DEC2HEX(HEX2DEC(M6)+1) -> 4 | N7: =LEFT($S7, 8) | O7: =MID($S7, 9, 8) | P7: =MID($S7, 17, 8) | Q7: ="[" &$B$7 & "]" -> [PAP_TR] | R7: {=IF(N7="","",(_xlfn.LAMBDA(_xlpm.x,LEFT(_xlpm.x&REPT(" ",8),8))($N7) & _xlfn.LAMBDA(_xlpm.x,LEFT(_xlpm.x&REPT(" ",8),8))($O7) & _xlfn.LAMBDA(_xlpm.x,LEFT(_xlpm.x&REPT(" ",8),8))(P7) & _xlfn.LAMBDA(_xlpm.x,LEFT(_xlpm.x&REPT(" ",8),8))($Q7)))}
D8: =D7+1 -> 6 | E8: =E7+1 -> 9506 | F8: =IF(K8="","",($B$7 & " ")) | G8: =MID($K8, 9, 8) | H8: =MID($K8, 17, 8) | I8: ="[" &$B$7 & "]" -> [PAP_TR] | J8: {=IF(F8="","",_xlfn.LAMBDA(_xlpm.x,LEFT(_xlpm.x&REPT(" ",8),8))($F8) & _xlfn.LAMBDA(_xlpm.x,LEFT(_xlpm.x&REPT(" ",8),8))($G8) & _xlfn.LAMBDA(_xlpm.x,LEFT(_xlpm.x&REPT(" ",8),8))($H8) & _xlfn.LAMBDA(_xlpm.x,LEFT(_xlpm.x&REPT(" ",8),8))($I8))} | L8: =L7 -> 9500 | M8: =DEC2HEX(HEX2DEC(M7)+1) -> 5 | N8: =LEFT($S8, 8) | O8: =MID($S8, 9, 8) | P8: =MID($S8, 17, 8) | Q8: ="[" &$B$7 & "]" -> [PAP_TR] | R8: {=IF(N8="","",(_xlfn.LAMBDA(_xlpm.x,LEFT(_xlpm.x&REPT(" ",8),8))($N8) & _xlfn.LAMBDA(_xlpm.x,LEFT(_xlpm.x&REPT(" ",8),8))($O8) & _xlfn.LAMBDA(_xlpm.x,LEFT(_xlpm.x&REPT(" ",8),8))(P8) & _xlfn.LAMBDA(_xlpm.x,LEFT(_xlpm.x&REPT(" ",8),8))($Q8)))}
D9: =D8+1 -> 7 | E9: =E8+1 -> 9507 | F9: =IF(K9="","",($B$7 & " ")) | G9: =MID($K9, 9, 8) | H9: =MID($K9, 17, 8) | I9: ="[" &$B$7 & "]" -> [PAP_TR] | J9: {=IF(F9="","",_xlfn.LAMBDA(_xlpm.x,LEFT(_xlpm.x&REPT(" ",8),8))($F9) & _xlfn.LAMBDA(_xlpm.x,LEFT(_xlpm.x&REPT(" ",8),8))($G9) & _xlfn.LAMBDA(_xlpm.x,LEFT(_xlpm.x&REPT(" ",8),8))($H9) & _xlfn.LAMBDA(_xlpm.x,LEFT(_xlpm.x&REPT(" ",8),8))($I9))} | L9: =L8 -> 9500 | M9: =DEC2HEX(HEX2DEC(M8)+1) -> 6 | N9: =LEFT($S9, 8) | O9: =MID($S9, 9, 8) | P9: =MID($S9, 17, 8) | Q9: ="[" &$B$7 & "]" -> [PAP_TR] | R9: {=IF(N9="","",(_xlfn.LAMBDA(_xlpm.x,LEFT(_xlpm.x&REPT(" ",8),8))($N9) & _xlfn.LAMBDA(_xlpm.x,LEFT(_xlpm.x&REPT(" ",8),8))($O9) & _xlfn.LAMBDA(_xlpm.x,LEFT(_xlpm.x&REPT(" ",8),8))(P9) & _xlfn.LAMBDA(_xlpm.x,LEFT(_xlpm.x&REPT(" ",8),8))($Q9)))}
D10: =D9+1 -> 8 | E10: =E9+1 -> 9508 | F10: =IF(K10="","",($B$7 & " ")) | G10: =MID($K10, 9, 8) | H10: =MID($K10, 17, 8) | I10: ="[" &$B$7 & "]" -> [PAP_TR] | J10: {=IF(F10="","",_xlfn.LAMBDA(_xlpm.x,LEFT(_xlpm.x&REPT(" ",8),8))($F10) & _xlfn.LAMBDA(_xlpm.x,LEFT(_xlpm.x&REPT(" ",8),8))($G10) & _xlfn.LAMBDA(_xlpm.x,LEFT(_xlpm.x&REPT(" ",8),8))($H10) & _xlfn.LAMBDA(_xlpm.x,LEFT(_xlpm.x&REPT(" ",8),8))($I10))} | L10: =L9 -> 9500 | M10: =DEC2HEX(HEX2DEC(M9)+1) -> 7 | N10: =LEFT($S10, 8) | O10: =MID($S10, 9, 8) | P10: =MID($S10, 17, 8) | Q10: ="[" &$B$7 & "]" -> [PAP_TR] | R10: {=IF(N10="","",(_xlfn.LAMBDA(_xlpm.x,LEFT(_xlpm.x&REPT(" ",8),8))($N10) & _xlfn.LAMBDA(_xlpm.x,LEFT(_xlpm.x&REPT(" ",8),8))($O10) & _xlfn.LAMBDA(_xlpm.x,LEFT(_xlpm.x&REPT(" ",8),8))(P10) & _xlfn.LAMBDA(_xlpm.x,LEFT(_xlpm.x&REPT(" ",8),8))($Q10)))}
D11: =D10+1 -> 9 | E11: =E10+1 -> 9509 | F11: =IF(K11="","",($B$7 & " ")) | G11: =MID($K11, 9, 8) | H11: =MID($K11, 17, 8) | I11: ="[" &$B$7 & "]" -> [PAP_TR] | J11: {=IF(F11="","",_xlfn.LAMBDA(_xlpm.x,LEFT(_xlpm.x&REPT(" ",8),8))($F11) & _xlfn.LAMBDA(_xlpm.x,LEFT(_xlpm.x&REPT(" ",8),8))($G11) & _xlfn.LAMBDA(_xlpm.x,LEFT(_xlpm.x&REPT(" ",8),8))($H11) & _xlfn.LAMBDA(_xlpm.x,LEFT(_xlpm.x&REPT(" ",8),8))($I11))} | L11: =L10 -> 9500 | M11: =DEC2HEX(HEX2DEC(M10)+1) -> 8 | N11: =LEFT($S11, 8) | O11: =MID($S11, 9, 8) | P11: =MID($S11, 17, 8) | Q11: ="[" &$B$7 & "]" -> [PAP_TR] | R11: {=IF(N11="","",(_xlfn.LAMBDA(_xlpm.x,LEFT(_xlpm.x&REPT(" ",8),8))($N11) & _xlfn.LAMBDA(_xlpm.x,LEFT(_xlpm.x&REPT(" ",8),8))($O11) & _xlfn.LAMBDA(_xlpm.x,LEFT(_xlpm.x&REPT(" ",8),8))(P11) & _xlfn.LAMBDA(_xlpm.x,LEFT(_xlpm.x&REPT(" ",8),8))($Q11)))}
D12: =D11+1 -> 10 | E12: =E11+1 -> 9510 | F12: =IF(K12="","",($B$7 & " ")) -> PAP_TR | G12: =MID($K12, 9, 8) -> Cyl1 | H12: =MID($K12, 17, 8) -> Up Chk | I12: ="[" &$B$7 & "]" -> [PAP_TR] | J12: {=IF(F12="","",_xlfn.LAMBDA(_xlpm.x,LEFT(_xlpm.x&REPT(" ",8),8))($F12) & _xlfn.LAMBDA(_xlpm.x,LEFT(_xlpm.x&REPT(" ",8),8))($G12) & _xlfn.LAMBDA(_xlpm.x,LEFT(_xlpm.x&REPT(" ",8),8))($H12) & _xlfn.LAMBDA(_xlpm.x,LEFT(_xlpm.x&REPT(" ",8),8))($I12))} -> PAP_TR Cyl1 Up Chk [PAP_TR] | K12: NGICV1 Cyl1 Up Chk [NGICV1] | L12: =L11 -> 9500 | M12: =DEC2HEX(HEX2DEC(M11)+1) -> 9 | N12: =LEFT($S12, 8) | O12: =MID($S12, 9, 8) | P12: =MID($S12, 17, 8) | Q12: ="[" &$B$7 & "]" -> [PAP_TR] | R12: {=IF(N12="","",(_xlfn.LAMBDA(_xlpm.x,LEFT(_xlpm.x&REPT(" ",8),8))($N12) & _xlfn.LAMBDA(_xlpm.x,LEFT(_xlpm.x&REPT(" ",8),8))($O12) & _xlfn.LAMBDA(_xlpm.x,LEFT(_xlpm.x&REPT(" ",8),8))(P12) & _xlfn.LAMBDA(_xlpm.x,LEFT(_xlpm.x&REPT(" ",8),8))($Q12)))}
D13: =D12+1 -> 11 | E13: =E12+1 -> 9511 | F13: =IF(K13="","",($B$7 & " ")) -> PAP_TR | G13: =MID($K13, 9, 8) -> Cyl1 | H13: =MID($K13, 17, 8) -> Dwn Chk | I13: ="[" &$B$7 & "]" -> [PAP_TR] | J13: {=IF(F13="","",_xlfn.LAMBDA(_xlpm.x,LEFT(_xlpm.x&REPT(" ",8),8))($F13) & _xlfn.LAMBDA(_xlpm.x,LEFT(_xlpm.x&REPT(" ",8),8))($G13) & _xlfn.LAMBDA(_xlpm.x,LEFT(_xlpm.x&REPT(" ",8),8))($H13) & _xlfn.LAMBDA(_xlpm.x,LEFT(_xlpm.x&REPT(" ",8),8))($I13))} -> PAP_TR Cyl1 Dwn Chk [PAP_TR] | K13: NGICV1 Cyl1 Dwn Chk [NGICV1] | L13: =L12 -> 9500 | M13: =DEC2HEX(HEX2DEC(M12)+1) -> A | N13: =LEFT($S13, 8) | O13: =MID($S13, 9, 8) | P13: =MID($S13, 17, 8) | Q13: ="[" &$B$7 & "]" -> [PAP_TR] | R13: {=IF(N13="","",(_xlfn.LAMBDA(_xlpm.x,LEFT(_xlpm.x&REPT(" ",8),8))($N13) & _xlfn.LAMBDA(_xlpm.x,LEFT(_xlpm.x&REPT(" ",8),8))($O13) & _xlfn.LAMBDA(_xlpm.x,LEFT(_xlpm.x&REPT(" ",8),8))(P13) & _xlfn.LAMBDA(_xlpm.x,LEFT(_xlpm.x&REPT(" ",8),8))($Q13)))}
D14: =D13+1 -> 12 | E14: =E13+1 -> 9512 | F14: =IF(K14="","",($B$7 & " ")) -> PAP_TR | G14: =MID($K14, 9, 8) -> Cyl2 | H14: =MID($K14, 17, 8) -> Up Chk | I14: ="[" &$B$7 & "]" -> [PAP_TR] | J14: {=IF(F14="","",_xlfn.LAMBDA(_xlpm.x,LEFT(_xlpm.x&REPT(" ",8),8))($F14) & _xlfn.LAMBDA(_xlpm.x,LEFT(_xlpm.x&REPT(" ",8),8))($G14) & _xlfn.LAMBDA(_xlpm.x,LEFT(_xlpm.x&REPT(" ",8),8))($H14) & _xlfn.LAMBDA(_xlpm.x,LEFT(_xlpm.x&REPT(" ",8),8))($I14))} -> PAP_TR Cyl2 Up Chk [PAP_TR] | K14: NGICV1 Cyl2 Up Chk [NGICV1] | L14: =L13 -> 9500 | M14: =DEC2HEX(HEX2DEC(M13)+1) -> B | N14: =LEFT($S14, 8) | O14: =MID($S14, 9, 8) | P14: =MID($S14, 17, 8) | Q14: ="[" &$B$7 & "]" -> [PAP_TR] | R14: {=IF(N14="","",(_xlfn.LAMBDA(_xlpm.x,LEFT(_xlpm.x&REPT(" ",8),8))($N14) & _xlfn.LAMBDA(_xlpm.x,LEFT(_xlpm.x&REPT(" ",8),8))($O14) & _xlfn.LAMBDA(_xlpm.x,LEFT(_xlpm.x&REPT(" ",8),8))(P14) & _xlfn.LAMBDA(_xlpm.x,LEFT(_xlpm.x&REPT(" ",8),8))($Q14)))}
D15: =D14+1 -> 13 | E15: =E14+1 -> 9513 | F15: =IF(K15="","",($B$7 & " ")) -> PAP_TR | G15: =MID($K15, 9, 8) -> Cyl2 | H15: =MID($K15, 17, 8) -> Dwn Chk | I15: ="[" &$B$7 & "]" -> [PAP_TR] | J15: {=IF(F15="","",_xlfn.LAMBDA(_xlpm.x,LEFT(_xlpm.x&REPT(" ",8),8))($F15) & _xlfn.LAMBDA(_xlpm.x,LEFT(_xlpm.x&REPT(" ",8),8))($G15) & _xlfn.LAMBDA(_xlpm.x,LEFT(_xlpm.x&REPT(" ",8),8))($H15) & _xlfn.LAMBDA(_xlpm.x,LEFT(_xlpm.x&REPT(" ",8),8))($I15))} -> PAP_TR Cyl2 Dwn Chk [PAP_TR] | K15: NGICV1 Cyl2 Dwn Chk [NGICV1] | L15: =L14 -> 9500 | M15: =DEC2HEX(HEX2DEC(M14)+1) -> C | N15: =LEFT($S15, 8) | O15: =MID($S15, 9, 8) | P15: =MID($S15, 17, 8) | Q15: ="[" &$B$7 & "]" -> [PAP_TR] | R15: {=IF(N15="","",(_xlfn.LAMBDA(_xlpm.x,LEFT(_xlpm.x&REPT(" ",8),8))($N15) & _xlfn.LAMBDA(_xlpm.x,LEFT(_xlpm.x&REPT(" ",8),8))($O15) & _xlfn.LAMBDA(_xlpm.x,LEFT(_xlpm.x&REPT(" ",8),8))(P15) & _xlfn.LAMBDA(_xlpm.x,LEFT(_xlpm.x&REPT(" ",8),8))($Q15)))}
D16: =D15+1 -> 14 | E16: =E15+1 -> 9514 | F16: =IF(K16="","",($B$7 & " ")) -> PAP_TR | G16: =MID($K16, 9, 8) -> Cyl3 | H16: =MID($K16, 17, 8) -> Up Chk | I16: ="[" &$B$7 & "]" -> [PAP_TR] | J16: {=IF(F16="","",_xlfn.LAMBDA(_xlpm.x,LEFT(_xlpm.x&REPT(" ",8),8))($F16) & _xlfn.LAMBDA(_xlpm.x,LEFT(_xlpm.x&REPT(" ",8),8))($G16) & _xlfn.LAMBDA(_xlpm.x,LEFT(_xlpm.x&REPT(" ",8),8))($H16) & _xlfn.LAMBDA(_xlpm.x,LEFT(_xlpm.x&REPT(" ",8),8))($I16))} -> PAP_TR Cyl3 Up Chk [PAP_TR] | K16: NGICV1 Cyl3 Up Chk [NGICV1] | L16: =L15 -> 9500 | M16: =DEC2HEX(HEX2DEC(M15)+1) -> D | N16: =LEFT($S16, 8) | O16: =MID($S16, 9, 8) | P16: =MID($S16, 17, 8) | Q16: ="[" &$B$7 & "]" -> [PAP_TR] | R16: {=IF(N16="","",(_xlfn.LAMBDA(_xlpm.x,LEFT(_xlpm.x&REPT(" ",8),8))($N16) & _xlfn.LAMBDA(_xlpm.x,LEFT(_xlpm.x&REPT(" ",8),8))($O16) & _xlfn.LAMBDA(_xlpm.x,LEFT(_xlpm.x&REPT(" ",8),8))(P16) & _xlfn.LAMBDA(_xlpm.x,LEFT(_xlpm.x&REPT(" ",8),8))($Q16)))}
D17: =D16+1 -> 15 | E17: =E16+1 -> 9515 | F17: =IF(K17="","",($B$7 & " ")) -> PAP_TR | G17: =MID($K17, 9, 8) -> Cyl3 | H17: =MID($K17, 17, 8) -> Dwn Chk | I17: ="[" &$B$7 & "]" -> [PAP_TR] | J17: {=IF(F17="","",_xlfn.LAMBDA(_xlpm.x,LEFT(_xlpm.x&REPT(" ",8),8))($F17) & _xlfn.LAMBDA(_xlpm.x,LEFT(_xlpm.x&REPT(" ",8),8))($G17) & _xlfn.LAMBDA(_xlpm.x,LEFT(_xlpm.x&REPT(" ",8),8))($H17) & _xlfn.LAMBDA(_xlpm.x,LEFT(_xlpm.x&REPT(" ",8),8))($I17))} -> PAP_TR Cyl3 Dwn Chk [PAP_TR] | K17: NGICV1 Cyl3 Dwn Chk [NGICV1] | L17: =L16 -> 9500 | M17: =DEC2HEX(HEX2DEC(M16)+1) -> E | N17: =LEFT($S17, 8) | O17: =MID($S17, 9, 8) | P17: =MID($S17, 17, 8) | Q17: ="[" &$B$7 & "]" -> [PAP_TR] | R17: {=IF(N17="","",(_xlfn.LAMBDA(_xlpm.x,LEFT(_xlpm.x&REPT(" ",8),8))($N17) & _xlfn.LAMBDA(_xlpm.x,LEFT(_xlpm.x&REPT(" ",8),8))($O17) & _xlfn.LAMBDA(_xlpm.x,LEFT(_xlpm.x&REPT(" ",8),8))(P17) & _xlfn.LAMBDA(_xlpm.x,LEFT(_xlpm.x&REPT(" ",8),8))($Q17)))}
D18: =D17+1 -> 16 | E18: =E17+1 -> 9516 | F18: =IF(K18="","",($B$7 & " ")) | G18: =MID($K18, 9, 8) | H18: =MID($K18, 17, 8) | I18: ="[" &$B$7 & "]" -> [PAP_TR] | J18: {=IF(F18="","",_xlfn.LAMBDA(_xlpm.x,LEFT(_xlpm.x&REPT(" ",8),8))($F18) & _xlfn.LAMBDA(_xlpm.x,LEFT(_xlpm.x&REPT(" ",8),8))($G18) & _xlfn.LAMBDA(_xlpm.x,LEFT(_xlpm.x&REPT(" ",8),8))($H18) & _xlfn.LAMBDA(_xlpm.x,LEFT(_xlpm.x&REPT(" ",8),8))($I18))} | L18: =L17 -> 9500 | M18: =DEC2HEX(HEX2DEC(M17)+1) -> F | N18: =LEFT($S18, 8) | O18: =MID($S18, 9, 8) | P18: =MID($S18, 17, 8) | Q18: ="[" &$B$7 & "]" -> [PAP_TR] | R18: {=IF(N18="","",(_xlfn.LAMBDA(_xlpm.x,LEFT(_xlpm.x&REPT(" ",8),8))($N18) & _xlfn.LAMBDA(_xlpm.x,LEFT(_xlpm.x&REPT(" ",8),8))($O18) & _xlfn.LAMBDA(_xlpm.x,LEFT(_xlpm.x&REPT(" ",8),8))(P18) & _xlfn.LAMBDA(_xlpm.x,LEFT(_xlpm.x&REPT(" ",8),8))($Q18)))}
D19: =D18+1 -> 17 | E19: =E18+1 -> 9517 | F19: =IF(K19="","",($B$7 & " ")) | G19: =MID($K19, 9, 8) | H19: =MID($K19, 17, 8) | I19: ="[" &$B$7 & "]" -> [PAP_TR] | J19: {=IF(F19="","",_xlfn.LAMBDA(_xlpm.x,LEFT(_xlpm.x&REPT(" ",8),8))($F19) & _xlfn.LAMBDA(_xlpm.x,LEFT(_xlpm.x&REPT(" ",8),8))($G19) & _xlfn.LAMBDA(_xlpm.x,LEFT(_xlpm.x&REPT(" ",8),8))($H19) & _xlfn.LAMBDA(_xlpm.x,LEFT(_xlpm.x&REPT(" ",8),8))($I19))} | L19: =L2+1 -> 9501 | M19: =M2 -> - | N19: =LEFT($S19, 8) | O19: =MID($S19, 9, 8) | P19: =MID($S19, 17, 8) | Q19: ="[" &$B$7 & "]" -> [PAP_TR] | R19: {=IF(N19="","",(_xlfn.LAMBDA(_xlpm.x,LEFT(_xlpm.x&REPT(" ",8),8))($N19) & _xlfn.LAMBDA(_xlpm.x,LEFT(_xlpm.x&REPT(" ",8),8))($O19) & _xlfn.LAMBDA(_xlpm.x,LEFT(_xlpm.x&REPT(" ",8),8))(P19) & _xlfn.LAMBDA(_xlpm.x,LEFT(_xlpm.x&REPT(" ",8),8))($Q19)))}
D20: =D19+1 -> 18 | E20: =E19+1 -> 9518 | F20: =IF(K20="","",($B$7 & " ")) | G20: =MID($K20, 9, 8) | H20: =MID($K20, 17, 8) | I20: ="[" &$B$7 & "]" -> [PAP_TR] | J20: {=IF(F20="","",_xlfn.LAMBDA(_xlpm.x,LEFT(_xlpm.x&REPT(" ",8),8))($F20) & _xlfn.LAMBDA(_xlpm.x,LEFT(_xlpm.x&REPT(" ",8),8))($G20) & _xlfn.LAMBDA(_xlpm.x,LEFT(_xlpm.x&REPT(" ",8),8))($H20) & _xlfn.LAMBDA(_xlpm.x,LEFT(_xlpm.x&REPT(" ",8),8))($I20))} | L20: =L19 -> 9501 | M20: =M3 -> 0 | N20: =LEFT($S20, 8) | O20: =MID($S20, 9, 8) | P20: =MID($S20, 17, 8) | Q20: ="[" &$B$7 & "]" -> [PAP_TR] | R20: {=IF(N20="","",(_xlfn.LAMBDA(_xlpm.x,LEFT(_xlpm.x&REPT(" ",8),8))($N20) & _xlfn.LAMBDA(_xlpm.x,LEFT(_xlpm.x&REPT(" ",8),8))($O20) & _xlfn.LAMBDA(_xlpm.x,LEFT(_xlpm.x&REPT(" ",8),8))(P20) & _xlfn.LAMBDA(_xlpm.x,LEFT(_xlpm.x&REPT(" ",8),8))($Q20)))}
D21: =D20+1 -> 19 | E21: =E20+1 -> 9519 | F21: =IF(K21="","",($B$7 & " ")) | G21: =MID($K21, 9, 8) | H21: =MID($K21, 17, 8) | I21: ="[" &$B$7 & "]" -> [PAP_TR] | J21: {=IF(F21="","",_xlfn.LAMBDA(_xlpm.x,LEFT(_xlpm.x&REPT(" ",8),8))($F21) & _xlfn.LAMBDA(_xlpm.x,LEFT(_xlpm.x&REPT(" ",8),8))($G21) & _xlfn.LAMBDA(_xlpm.x,LEFT(_xlpm.x&REPT(" ",8),8))($H21) & _xlfn.LAMBDA(_xlpm.x,LEFT(_xlpm.x&REPT(" ",8),8))($I21))} | L21: =L20 -> 9501 | M21: =DEC2HEX(HEX2DEC(M20)+1) -> 1 | N21: =LEFT($S21, 8) | O21: =MID($S21, 9, 8) | P21: =MID($S21, 17, 8) | Q21: ="[" &$B$7 & "]" -> [PAP_TR] | R21: {=IF(N21="","",(_xlfn.LAMBDA(_xlpm.x,LEFT(_xlpm.x&REPT(" ",8),8))($N21) & _xlfn.LAMBDA(_xlpm.x,LEFT(_xlpm.x&REPT(" ",8),8))($O21) & _xlfn.LAMBDA(_xlpm.x,LEFT(_xlpm.x&REPT(" ",8),8))(P21) & _xlfn.LAMBDA(_xlpm.x,LEFT(_xlpm.x&REPT(" ",8),8))($Q21)))}
D22: =D21+1 -> 20 | E22: =E21+1 -> 9520 | F22: =IF(K22="","",($B$7 & " ")) | G22: =MID($K22, 9, 8) | H22: =MID($K22, 17, 8) | I22: ="[" &$B$7 & "]" -> [PAP_TR] | J22: {=IF(F22="","",_xlfn.LAMBDA(_xlpm.x,LEFT(_xlpm.x&REPT(" ",8),8))($F22) & _xlfn.LAMBDA(_xlpm.x,LEFT(_xlpm.x&REPT(" ",8),8))($G22) & _xlfn.LAMBDA(_xlpm.x,LEFT(_xlpm.x&REPT(" ",8),8))($H22) & _xlfn.LAMBDA(_xlpm.x,LEFT(_xlpm.x&REPT(" ",8),8))($I22))} | L22: =L21 -> 9501 | M22: =DEC2HEX(HEX2DEC(M21)+1) -> 2 | N22: =LEFT($S22, 8) | O22: =MID($S22, 9, 8) | P22: =MID($S22, 17, 8) | Q22: ="[" &$B$7 & "]" -> [PAP_TR] | R22: {=IF(N22="","",(_xlfn.LAMBDA(_xlpm.x,LEFT(_xlpm.x&REPT(" ",8),8))($N22) & _xlfn.LAMBDA(_xlpm.x,LEFT(_xlpm.x&REPT(" ",8),8))($O22) & _xlfn.LAMBDA(_xlpm.x,LEFT(_xlpm.x&REPT(" ",8),8))(P22) & _xlfn.LAMBDA(_xlpm.x,LEFT(_xlpm.x&REPT(" ",8),8))($Q22)))}
D23: =D22+1 -> 21 | E23: =E22+1 -> 9521 | F23: =IF(K23="","",($B$7 & " ")) | G23: =MID($K23, 9, 8) | H23: =MID($K23, 17, 8) | I23: ="[" &$B$7 & "]" -> [PAP_TR] | J23: {=IF(F23="","",_xlfn.LAMBDA(_xlpm.x,LEFT(_xlpm.x&REPT(" ",8),8))($F23) & _xlfn.LAMBDA(_xlpm.x,LEFT(_xlpm.x&REPT(" ",8),8))($G23) & _xlfn.LAMBDA(_xlpm.x,LEFT(_xlpm.x&REPT(" ",8),8))($H23) & _xlfn.LAMBDA(_xlpm.x,LEFT(_xlpm.x&REPT(" ",8),8))($I23))} | L23: =L22 -> 9501 | M23: =DEC2HEX(HEX2DEC(M22)+1) -> 3 | N23: =LEFT($S23, 8) | O23: =MID($S23, 9, 8) | P23: =MID($S23, 17, 8) | Q23: ="[" &$B$7 & "]" -> [PAP_TR] | R23: {=IF(N23="","",(_xlfn.LAMBDA(_xlpm.x,LEFT(_xlpm.x&REPT(" ",8),8))($N23) & _xlfn.LAMBDA(_xlpm.x,LEFT(_xlpm.x&REPT(" ",8),8))($O23) & _xlfn.LAMBDA(_xlpm.x,LEFT(_xlpm.x&REPT(" ",8),8))(P23) & _xlfn.LAMBDA(_xlpm.x,LEFT(_xlpm.x&REPT(" ",8),8))($Q23)))}
D24: =D23+1 -> 22 | E24: =E23+1 -> 9522 | F24: =IF(K24="","",($B$7 & " ")) | G24: =MID($K24, 9, 8) | H24: =MID($K24, 17, 8) | I24: ="[" &$B$7 & "]" -> [PAP_TR] | J24: {=IF(F24="","",_xlfn.LAMBDA(_xlpm.x,LEFT(_xlpm.x&REPT(" ",8),8))($F24) & _xlfn.LAMBDA(_xlpm.x,LEFT(_xlpm.x&REPT(" ",8),8))($G24) & _xlfn.LAMBDA(_xlpm.x,LEFT(_xlpm.x&REPT(" ",8),8))($H24) & _xlfn.LAMBDA(_xlpm.x,LEFT(_xlpm.x&REPT(" ",8),8))($I24))} | L24: =L23 -> 9501 | M24: =DEC2HEX(HEX2DEC(M23)+1) -> 4 | N24: =LEFT($S24, 8) | O24: =MID($S24, 9, 8) | P24: =MID($S24, 17, 8) | Q24: ="[" &$B$7 & "]" -> [PAP_TR] | R24: {=IF(N24="","",(_xlfn.LAMBDA(_xlpm.x,LEFT(_xlpm.x&REPT(" ",8),8))($N24) & _xlfn.LAMBDA(_xlpm.x,LEFT(_xlpm.x&REPT(" ",8),8))($O24) & _xlfn.LAMBDA(_xlpm.x,LEFT(_xlpm.x&REPT(" ",8),8))(P24) & _xlfn.LAMBDA(_xlpm.x,LEFT(_xlpm.x&REPT(" ",8),8))($Q24)))}
D25: =D24+1 -> 23 | E25: =E24+1 -> 9523 | F25: =IF(K25="","",($B$7 & " ")) | G25: =MID($K25, 9, 8) | H25: =MID($K25, 17, 8) | I25: ="[" &$B$7 & "]" -> [PAP_TR] | J25: {=IF(F25="","",_xlfn.LAMBDA(_xlpm.x,LEFT(_xlpm.x&REPT(" ",8),8))($F25) & _xlfn.LAMBDA(_xlpm.x,LEFT(_xlpm.x&REPT(" ",8),8))($G25) & _xlfn.LAMBDA(_xlpm.x,LEFT(_xlpm.x&REPT(" ",8),8))($H25) & _xlfn.LAMBDA(_xlpm.x,LEFT(_xlpm.x&REPT(" ",8),8))($I25))} | L25: =L24 -> 9501 | M25: =DEC2HEX(HEX2DEC(M24)+1) -> 5 | N25: =LEFT($S25, 8) | O25: =MID($S25, 9, 8) | P25: =MID($S25, 17, 8) | Q25: ="[" &$B$7 & "]" -> [PAP_TR] | R25: {=IF(N25="","",(_xlfn.LAMBDA(_xlpm.x,LEFT(_xlpm.x&REPT(" ",8),8))($N25) & _xlfn.LAMBDA(_xlpm.x,LEFT(_xlpm.x&REPT(" ",8),8))($O25) & _xlfn.LAMBDA(_xlpm.x,LEFT(_xlpm.x&REPT(" ",8),8))(P25) & _xlfn.LAMBDA(_xlpm.x,LEFT(_xlpm.x&REPT(" ",8),8))($Q25)))}
D26: =D25+1 -> 24 | E26: =E25+1 -> 9524 | F26: =IF(K26="","",($B$7 & " ")) | G26: =MID($K26, 9, 8) | H26: =MID($K26, 17, 8) | I26: ="[" &$B$7 & "]" -> [PAP_TR] | J26: {=IF(F26="","",_xlfn.LAMBDA(_xlpm.x,LEFT(_xlpm.x&REPT(" ",8),8))($F26) & _xlfn.LAMBDA(_xlpm.x,LEFT(_xlpm.x&REPT(" ",8),8))($G26) & _xlfn.LAMBDA(_xlpm.x,LEFT(_xlpm.x&REPT(" ",8),8))($H26) & _xlfn.LAMBDA(_xlpm.x,LEFT(_xlpm.x&REPT(" ",8),8))($I26))} | L26: =L25 -> 9501 | M26: =DEC2HEX(HEX2DEC(M25)+1) -> 6 | N26: =LEFT($S26, 8) | O26: =MID($S26, 9, 8) | P26: =MID($S26, 17, 8) | Q26: ="[" &$B$7 & "]" -> [PAP_TR] | R26: {=IF(N26="","",(_xlfn.LAMBDA(_xlpm.x,LEFT(_xlpm.x&REPT(" ",8),8))($N26) & _xlfn.LAMBDA(_xlpm.x,LEFT(_xlpm.x&REPT(" ",8),8))($O26) & _xlfn.LAMBDA(_xlpm.x,LEFT(_xlpm.x&REPT(" ",8),8))(P26) & _xlfn.LAMBDA(_xlpm.x,LEFT(_xlpm.x&REPT(" ",8),8))($Q26)))}
D27: =D26+1 -> 25 | E27: =E26+1 -> 9525 | F27: =IF(K27="","",($B$7 & " ")) | G27: =MID($K27, 9, 8) | H27: =MID($K27, 17, 8) | I27: ="[" &$B$7 & "]" -> [PAP_TR] | J27: {=IF(F27="","",_xlfn.LAMBDA(_xlpm.x,LEFT(_xlpm.x&REPT(" ",8),8))($F27) & _xlfn.LAMBDA(_xlpm.x,LEFT(_xlpm.x&REPT(" ",8),8))($G27) & _xlfn.LAMBDA(_xlpm.x,LEFT(_xlpm.x&REPT(" ",8),8))($H27) & _xlfn.LAMBDA(_xlpm.x,LEFT(_xlpm.x&REPT(" ",8),8))($I27))} | L27: =L26 -> 9501 | M27: =DEC2HEX(HEX2DEC(M26)+1) -> 7 | N27: =LEFT($S27, 8) | O27: =MID($S27, 9, 8) | P27: =MID($S27, 17, 8) | Q27: ="[" &$B$7 & "]" -> [PAP_TR] | R27: {=IF(N27="","",(_xlfn.LAMBDA(_xlpm.x,LEFT(_xlpm.x&REPT(" ",8),8))($N27) & _xlfn.LAMBDA(_xlpm.x,LEFT(_xlpm.x&REPT(" ",8),8))($O27) & _xlfn.LAMBDA(_xlpm.x,LEFT(_xlpm.x&REPT(" ",8),8))(P27) & _xlfn.LAMBDA(_xlpm.x,LEFT(_xlpm.x&REPT(" ",8),8))($Q27)))}
D28: =D27+1 -> 26 | E28: =E27+1 -> 9526 | F28: =IF(K28="","",($B$7 & " ")) | G28: =MID($K28, 9, 8) | H28: =MID($K28, 17, 8) | I28: ="[" &$B$7 & "]" -> [PAP_TR] | J28: {=IF(F28="","",_xlfn.LAMBDA(_xlpm.x,LEFT(_xlpm.x&REPT(" ",8),8))($F28) & _xlfn.LAMBDA(_xlpm.x,LEFT(_xlpm.x&REPT(" ",8),8))($G28) & _xlfn.LAMBDA(_xlpm.x,LEFT(_xlpm.x&REPT(" ",8),8))($H28) & _xlfn.LAMBDA(_xlpm.x,LEFT(_xlpm.x&REPT(" ",8),8))($I28))} | L28: =L27 -> 9501 | M28: =DEC2HEX(HEX2DEC(M27)+1) -> 8 | N28: =LEFT($S28, 8) | O28: =MID($S28, 9, 8) | P28: =MID($S28, 17, 8) | Q28: ="[" &$B$7 & "]" -> [PAP_TR] | R28: {=IF(N28="","",(_xlfn.LAMBDA(_xlpm.x,LEFT(_xlpm.x&REPT(" ",8),8))($N28) & _xlfn.LAMBDA(_xlpm.x,LEFT(_xlpm.x&REPT(" ",8),8))($O28) & _xlfn.LAMBDA(_xlpm.x,LEFT(_xlpm.x&REPT(" ",8),8))(P28) & _xlfn.LAMBDA(_xlpm.x,LEFT(_xlpm.x&REPT(" ",8),8))($Q28)))}
D29: =D28+1 -> 27 | E29: =E28+1 -> 9527 | F29: =IF(K29="","",($B$7 & " ")) | G29: =MID($K29, 9, 8) | H29: =MID($K29, 17, 8) | I29: ="[" &$B$7 & "]" -> [PAP_TR] | J29: {=IF(F29="","",_xlfn.LAMBDA(_xlpm.x,LEFT(_xlpm.x&REPT(" ",8),8))($F29) & _xlfn.LAMBDA(_xlpm.x,LEFT(_xlpm.x&REPT(" ",8),8))($G29) & _xlfn.LAMBDA(_xlpm.x,LEFT(_xlpm.x&REPT(" ",8),8))($H29) & _xlfn.LAMBDA(_xlpm.x,LEFT(_xlpm.x&REPT(" ",8),8))($I29))} | L29: =L28 -> 9501 | M29: =DEC2HEX(HEX2DEC(M28)+1) -> 9 | N29: =LEFT($S29, 8) | O29: =MID($S29, 9, 8) | P29: =MID($S29, 17, 8) | Q29: ="[" &$B$7 & "]" -> [PAP_TR] | R29: {=IF(N29="","",(_xlfn.LAMBDA(_xlpm.x,LEFT(_xlpm.x&REPT(" ",8),8))($N29) & _xlfn.LAMBDA(_xlpm.x,LEFT(_xlpm.x&REPT(" ",8),8))($O29) & _xlfn.LAMBDA(_xlpm.x,LEFT(_xlpm.x&REPT(" ",8),8))(P29) & _xlfn.LAMBDA(_xlpm.x,LEFT(_xlpm.x&REPT(" ",8),8))($Q29)))}
D30: =D29+1 -> 28 | E30: =E29+1 -> 9528 | F30: =IF(K30="","",($B$7 & " ")) | G30: =MID($K30, 9, 8) | H30: =MID($K30, 17, 8) | I30: ="[" &$B$7 & "]" -> [PAP_TR] | J30: {=IF(F30="","",_xlfn.LAMBDA(_xlpm.x,LEFT(_xlpm.x&REPT(" ",8),8))($F30) & _xlfn.LAMBDA(_xlpm.x,LEFT(_xlpm.x&REPT(" ",8),8))($G30) & _xlfn.LAMBDA(_xlpm.x,LEFT(_xlpm.x&REPT(" ",8),8))($H30) & _xlfn.LAMBDA(_xlpm.x,LEFT(_xlpm.x&REPT(" ",8),8))($I30))} | L30: =L29 -> 9501 | M30: =DEC2HEX(HEX2DEC(M29)+1) -> A | N30: =LEFT($S30, 8) | O30: =MID($S30, 9, 8) | P30: =MID($S30, 17, 8) | Q30: ="[" &$B$7 & "]" -> [PAP_TR] | R30: {=IF(N30="","",(_xlfn.LAMBDA(_xlpm.x,LEFT(_xlpm.x&REPT(" ",8),8))($N30) & _xlfn.LAMBDA(_xlpm.x,LEFT(_xlpm.x&REPT(" ",8),8))($O30) & _xlfn.LAMBDA(_xlpm.x,LEFT(_xlpm.x&REPT(" ",8),8))(P30) & _xlfn.LAMBDA(_xlpm.x,LEFT(_xlpm.x&REPT(" ",8),8))($Q30)))}
D31: =D30+1 -> 29 | E31: =E30+1 -> 9529 | F31: =IF(K31="","",($B$7 & " ")) | G31: =MID($K31, 9, 8) | H31: =MID($K31, 17, 8) | I31: ="[" &$B$7 & "]" -> [PAP_TR] | J31: {=IF(F31="","",_xlfn.LAMBDA(_xlpm.x,LEFT(_xlpm.x&REPT(" ",8),8))($F31) & _xlfn.LAMBDA(_xlpm.x,LEFT(_xlpm.x&REPT(" ",8),8))($G31) & _xlfn.LAMBDA(_xlpm.x,LEFT(_xlpm.x&REPT(" ",8),8))($H31) & _xlfn.LAMBDA(_xlpm.x,LEFT(_xlpm.x&REPT(" ",8),8))($I31))} | L31: =L30 -> 9501 | M31: =DEC2HEX(HEX2DEC(M30)+1) -> B | N31: =LEFT($S31, 8) | O31: =MID($S31, 9, 8) | P31: =MID($S31, 17, 8) | Q31: ="[" &$B$7 & "]" -> [PAP_TR] | R31: {=IF(N31="","",(_xlfn.LAMBDA(_xlpm.x,LEFT(_xlpm.x&REPT(" ",8),8))($N31) & _xlfn.LAMBDA(_xlpm.x,LEFT(_xlpm.x&REPT(" ",8),8))($O31) & _xlfn.LAMBDA(_xlpm.x,LEFT(_xlpm.x&REPT(" ",8),8))(P31) & _xlfn.LAMBDA(_xlpm.x,LEFT(_xlpm.x&REPT(" ",8),8))($Q31)))}
D32: =D31+1 -> 30 | E32: =E31+1 -> 9530 | F32: =IF(K32="","",($B$7 & " ")) | G32: =MID($K32, 9, 8) | H32: =MID($K32, 17, 8) | I32: ="[" &$B$7 & "]" -> [PAP_TR] | J32: {=IF(F32="","",_xlfn.LAMBDA(_xlpm.x,LEFT(_xlpm.x&REPT(" ",8),8))($F32) & _xlfn.LAMBDA(_xlpm.x,LEFT(_xlpm.x&REPT(" ",8),8))($G32) & _xlfn.LAMBDA(_xlpm.x,LEFT(_xlpm.x&REPT(" ",8),8))($H32) & _xlfn.LAMBDA(_xlpm.x,LEFT(_xlpm.x&REPT(" ",8),8))($I32))} | L32: =L31 -> 9501 | M32: =DEC2HEX(HEX2DEC(M31)+1) -> C | N32: =LEFT($S32, 8) | O32: =MID($S32, 9, 8) | P32: =MID($S32, 17, 8) | Q32: ="[" &$B$7 & "]" -> [PAP_TR] | R32: {=IF(N32="","",(_xlfn.LAMBDA(_xlpm.x,LEFT(_xlpm.x&REPT(" ",8),8))($N32) & _xlfn.LAMBDA(_xlpm.x,LEFT(_xlpm.x&REPT(" ",8),8))($O32) & _xlfn.LAMBDA(_xlpm.x,LEFT(_xlpm.x&REPT(" ",8),8))(P32) & _xlfn.LAMBDA(_xlpm.x,LEFT(_xlpm.x&REPT(" ",8),8))($Q32)))}
... D35: =D34+1 -> 33 | E35: =E34+1 -> 9533 | F35: =IF(K35="","",($B$7 & " ")) | G35: =MID($K35, 9, 8) | H35: =MID($K35, 17, 8) | I35: ="[" &$B$7 & "]" -> [PAP_TR] | J35: {=IF(F35="","",_xlfn.LAMBDA(_xlpm.x,LEFT(_xlpm.x&REPT(" ",8),8))($F35) & _xlfn.LAMBDA(_xlpm.x,LEFT(_xlpm.x&REPT(" ",8),8))($G35) & _xlfn.LAMBDA(_xlpm.x,LEFT(_xlpm.x&REPT(" ",8),8))($H35) & _xlfn.LAMBDA(_xlpm.x,LEFT(_xlpm.x&REPT(" ",8),8))($I35))} | L35: =L34 -> 9501 | M35: =DEC2HEX(HEX2DEC(M34)+1) -> F | N35: =LEFT($S35, 8) | O35: =MID($S35, 9, 8) | P35: =MID($S35, 17, 8) | Q35: ="[" &$B$7 & "]" -> [PAP_TR] | R35: {=IF(N35="","",(_xlfn.LAMBDA(_xlpm.x,LEFT(_xlpm.x&REPT(" ",8),8))($N35) & _xlfn.LAMBDA(_xlpm.x,LEFT(_xlpm.x&REPT(" ",8),8))($O35) & _xlfn.LAMBDA(_xlpm.x,LEFT(_xlpm.x&REPT(" ",8),8))(P35) & _xlfn.LAMBDA(_xlpm.x,LEFT(_xlpm.x&REPT(" ",8),8))($Q35)))}
D36: =D35+1 -> 34 | E36: =E35+1 -> 9534 | F36: =IF(K36="","",($B$7 & " ")) | G36: =MID($K36, 9, 8) | H36: =MID($K36, 17, 8) | I36: ="[" &$B$7 & "]" -> [PAP_TR] | J36: {=IF(F36="","",_xlfn.LAMBDA(_xlpm.x,LEFT(_xlpm.x&REPT(" ",8),8))($F36) & _xlfn.LAMBDA(_xlpm.x,LEFT(_xlpm.x&REPT(" ",8),8))($G36) & _xlfn.LAMBDA(_xlpm.x,LEFT(_xlpm.x&REPT(" ",8),8))($H36) & _xlfn.LAMBDA(_xlpm.x,LEFT(_xlpm.x&REPT(" ",8),8))($I36))} | L36: =L19+1 -> 9502 | M36: =M19 -> - | N36: =LEFT($S36, 8) | O36: =MID($S36, 9, 8) | P36: =MID($S36, 17, 8) | Q36: ="[" &$B$7 & "]" -> [PAP_TR] | R36: {=IF(N36="","",(_xlfn.LAMBDA(_xlpm.x,LEFT(_xlpm.x&REPT(" ",8),8))($N36) & _xlfn.LAMBDA(_xlpm.x,LEFT(_xlpm.x&REPT(" ",8),8))($O36) & _xlfn.LAMBDA(_xlpm.x,LEFT(_xlpm.x&REPT(" ",8),8))(P36) & _xlfn.LAMBDA(_xlpm.x,LEFT(_xlpm.x&REPT(" ",8),8))($Q36)))}
D37: =D36+1 -> 35 | E37: =E36+1 -> 9535 | F37: =IF(K37="","",($B$7 & " ")) | G37: =MID($K37, 9, 8) | H37: =MID($K37, 17, 8) | I37: ="[" &$B$7 & "]" -> [PAP_TR] | J37: {=IF(F37="","",_xlfn.LAMBDA(_xlpm.x,LEFT(_xlpm.x&REPT(" ",8),8))($F37) & _xlfn.LAMBDA(_xlpm.x,LEFT(_xlpm.x&REPT(" ",8),8))($G37) & _xlfn.LAMBDA(_xlpm.x,LEFT(_xlpm.x&REPT(" ",8),8))($H37) & _xlfn.LAMBDA(_xlpm.x,LEFT(_xlpm.x&REPT(" ",8),8))($I37))} | L37: =L36 -> 9502 | M37: =M20 -> 0 | N37: =LEFT($S37, 8) | O37: =MID($S37, 9, 8) | P37: =MID($S37, 17, 8) | Q37: ="[" &$B$7 & "]" -> [PAP_TR] | R37: {=IF(N37="","",(_xlfn.LAMBDA(_xlpm.x,LEFT(_xlpm.x&REPT(" ",8),8))($N37) & _xlfn.LAMBDA(_xlpm.x,LEFT(_xlpm.x&REPT(" ",8),8))($O37) & _xlfn.LAMBDA(_xlpm.x,LEFT(_xlpm.x&REPT(" ",8),8))(P37) & _xlfn.LAMBDA(_xlpm.x,LEFT(_xlpm.x&REPT(" ",8),8))($Q37)))}
D38: =D37+1 -> 36 | E38: =E37+1 -> 9536 | F38: =IF(K38="","",($B$7 & " ")) | G38: =MID($K38, 9, 8) | H38: =MID($K38, 17, 8) | I38: ="[" &$B$7 & "]" -> [PAP_TR] | J38: {=IF(F38="","",_xlfn.LAMBDA(_xlpm.x,LEFT(_xlpm.x&REPT(" ",8),8))($F38) & _xlfn.LAMBDA(_xlpm.x,LEFT(_xlpm.x&REPT(" ",8),8))($G38) & _xlfn.LAMBDA(_xlpm.x,LEFT(_xlpm.x&REPT(" ",8),8))($H38) & _xlfn.LAMBDA(_xlpm.x,LEFT(_xlpm.x&REPT(" ",8),8))($I38))} | L38: =L37 -> 9502 | M38: =DEC2HEX(HEX2DEC(M37)+1) -> 1 | N38: =LEFT($S38, 8) | O38: =MID($S38, 9, 8) | P38: =MID($S38, 17, 8) | Q38: ="[" &$B$7 & "]" -> [PAP_TR] | R38: {=IF(N38="","",(_xlfn.LAMBDA(_xlpm.x,LEFT(_xlpm.x&REPT(" ",8),8))($N38) & _xlfn.LAMBDA(_xlpm.x,LEFT(_xlpm.x&REPT(" ",8),8))($O38) & _xlfn.LAMBDA(_xlpm.x,LEFT(_xlpm.x&REPT(" ",8),8))(P38) & _xlfn.LAMBDA(_xlpm.x,LEFT(_xlpm.x&REPT(" ",8),8))($Q38)))}
D39: =D38+1 -> 37 | E39: =E38+1 -> 9537 | F39: =IF(K39="","",($B$7 & " ")) | G39: =MID($K39, 9, 8) | H39: =MID($K39, 17, 8) | I39: ="[" &$B$7 & "]" -> [PAP_TR] | J39: {=IF(F39="","",_xlfn.LAMBDA(_xlpm.x,LEFT(_xlpm.x&REPT(" ",8),8))($F39) & _xlfn.LAMBDA(_xlpm.x,LEFT(_xlpm.x&REPT(" ",8),8))($G39) & _xlfn.LAMBDA(_xlpm.x,LEFT(_xlpm.x&REPT(" ",8),8))($H39) & _xlfn.LAMBDA(_xlpm.x,LEFT(_xlpm.x&REPT(" ",8),8))($I39))} | L39: =L38 -> 9502 | M39: =DEC2HEX(HEX2DEC(M38)+1) -> 2 | N39: =LEFT($S39, 8) | O39: =MID($S39, 9, 8) | P39: =MID($S39, 17, 8) | Q39: ="[" &$B$7 & "]" -> [PAP_TR] | R39: {=IF(N39="","",(_xlfn.LAMBDA(_xlpm.x,LEFT(_xlpm.x&REPT(" ",8),8))($N39) & _xlfn.LAMBDA(_xlpm.x,LEFT(_xlpm.x&REPT(" ",8),8))($O39) & _xlfn.LAMBDA(_xlpm.x,LEFT(_xlpm.x&REPT(" ",8),8))(P39) & _xlfn.LAMBDA(_xlpm.x,LEFT(_xlpm.x&REPT(" ",8),8))($Q39)))}
D40: =D39+1 -> 38 | E40: =E39+1 -> 9538 | F40: =IF(K40="","",($B$7 & " ")) | G40: =MID($K40, 9, 8) | H40: =MID($K40, 17, 8) | I40: ="[" &$B$7 & "]" -> [PAP_TR] | J40: {=IF(F40="","",_xlfn.LAMBDA(_xlpm.x,LEFT(_xlpm.x&REPT(" ",8),8))($F40) & _xlfn.LAMBDA(_xlpm.x,LEFT(_xlpm.x&REPT(" ",8),8))($G40) & _xlfn.LAMBDA(_xlpm.x,LEFT(_xlpm.x&REPT(" ",8),8))($H40) & _xlfn.LAMBDA(_xlpm.x,LEFT(_xlpm.x&REPT(" ",8),8))($I40))} | L40: =L39 -> 9502 | M40: =DEC2HEX(HEX2DEC(M39)+1) -> 3 | N40: =LEFT($S40, 8) | O40: =MID($S40, 9, 8) | P40: =MID($S40, 17, 8) | Q40: ="[" &$B$7 & "]" -> [PAP_TR] | R40: {=IF(N40="","",(_xlfn.LAMBDA(_xlpm.x,LEFT(_xlpm.x&REPT(" ",8),8))($N40) & _xlfn.LAMBDA(_xlpm.x,LEFT(_xlpm.x&REPT(" ",8),8))($O40) & _xlfn.LAMBDA(_xlpm.x,LEFT(_xlpm.x&REPT(" ",8),8))(P40) & _xlfn.LAMBDA(_xlpm.x,LEFT(_xlpm.x&REPT(" ",8),8))($Q40)))}
D41: =D40+1 -> 39 | E41: =E40+1 -> 9539 | F41: =IF(K41="","",($B$7 & " ")) | G41: =MID($K41, 9, 8) | H41: =MID($K41, 17, 8) | I41: ="[" &$B$7 & "]" -> [PAP_TR] | J41: {=IF(F41="","",_xlfn.LAMBDA(_xlpm.x,LEFT(_xlpm.x&REPT(" ",8),8))($F41) & _xlfn.LAMBDA(_xlpm.x,LEFT(_xlpm.x&REPT(" ",8),8))($G41) & _xlfn.LAMBDA(_xlpm.x,LEFT(_xlpm.x&REPT(" ",8),8))($H41) & _xlfn.LAMBDA(_xlpm.x,LEFT(_xlpm.x&REPT(" ",8),8))($I41))} | L41: =L40 -> 9502 | M41: =DEC2HEX(HEX2DEC(M40)+1) -> 4 | N41: =LEFT($S41, 8) | O41: =MID($S41, 9, 8) | P41: =MID($S41, 17, 8) | Q41: ="[" &$B$7 & "]" -> [PAP_TR] | R41: {=IF(N41="","",(_xlfn.LAMBDA(_xlpm.x,LEFT(_xlpm.x&REPT(" ",8),8))($N41) & _xlfn.LAMBDA(_xlpm.x,LEFT(_xlpm.x&REPT(" ",8),8))($O41) & _xlfn.LAMBDA(_xlpm.x,LEFT(_xlpm.x&REPT(" ",8),8))(P41) & _xlfn.LAMBDA(_xlpm.x,LEFT(_xlpm.x&REPT(" ",8),8))($Q41)))}
D42: =D41+1 -> 40 | E42: =E41+1 -> 9540 | F42: =IF(K42="","",($B$7 & " ")) | G42: =MID($K42, 9, 8) | H42: =MID($K42, 17, 8) | I42: ="[" &$B$7 & "]" -> [PAP_TR] | J42: {=IF(F42="","",_xlfn.LAMBDA(_xlpm.x,LEFT(_xlpm.x&REPT(" ",8),8))($F42) & _xlfn.LAMBDA(_xlpm.x,LEFT(_xlpm.x&REPT(" ",8),8))($G42) & _xlfn.LAMBDA(_xlpm.x,LEFT(_xlpm.x&REPT(" ",8),8))($H42) & _xlfn.LAMBDA(_xlpm.x,LEFT(_xlpm.x&REPT(" ",8),8))($I42))} | L42: =L41 -> 9502 | M42: =DEC2HEX(HEX2DEC(M41)+1) -> 5 | N42: =LEFT($S42, 8) | O42: =MID($S42, 9, 8) | P42: =MID($S42, 17, 8) | Q42: ="[" &$B$7 & "]" -> [PAP_TR] | R42: {=IF(N42="","",(_xlfn.LAMBDA(_xlpm.x,LEFT(_xlpm.x&REPT(" ",8),8))($N42) & _xlfn.LAMBDA(_xlpm.x,LEFT(_xlpm.x&REPT(" ",8),8))($O42) & _xlfn.LAMBDA(_xlpm.x,LEFT(_xlpm.x&REPT(" ",8),8))(P42) & _xlfn.LAMBDA(_xlpm.x,LEFT(_xlpm.x&REPT(" ",8),8))($Q42)))}
...
